[2025-03-05T08:59:34.086+0000] {local_task_job_runner.py:123} INFO - ::group::Pre task execution logs
[2025-03-05T08:59:34.100+0000] {taskinstance.py:2614} INFO - Dependencies all met for dep_context=non-requeueable deps ti=<TaskInstance: ml_pipeline_demo.prepare_data manual__2025-03-05T08:59:26.992165+00:00 [queued]>
[2025-03-05T08:59:34.106+0000] {taskinstance.py:2614} INFO - Dependencies all met for dep_context=requeueable deps ti=<TaskInstance: ml_pipeline_demo.prepare_data manual__2025-03-05T08:59:26.992165+00:00 [queued]>
[2025-03-05T08:59:34.107+0000] {taskinstance.py:2867} INFO - Starting attempt 1 of 1
[2025-03-05T08:59:34.118+0000] {taskinstance.py:2890} INFO - Executing <Task(PythonOperator): prepare_data> on 2025-03-05 08:59:26.992165+00:00
[2025-03-05T08:59:34.129+0000] {warnings.py:112} WARNING - /home/***/.local/lib/python3.12/site-packages/***/task/task_runner/standard_task_runner.py:70: DeprecationWarning: This process (pid=194) is multi-threaded, use of fork() may lead to deadlocks in the child.
  pid = os.fork()

[2025-03-05T08:59:34.132+0000] {standard_task_runner.py:72} INFO - Started process 207 to run task
[2025-03-05T08:59:34.132+0000] {standard_task_runner.py:104} INFO - Running: ['***', 'tasks', 'run', 'ml_pipeline_demo', 'prepare_data', 'manual__2025-03-05T08:59:26.992165+00:00', '--job-id', '8', '--raw', '--subdir', 'DAGS_FOLDER/ml_pipeline.py', '--cfg-path', '/tmp/tmpnelqe1af']
[2025-03-05T08:59:34.133+0000] {standard_task_runner.py:105} INFO - Job 8: Subtask prepare_data
[2025-03-05T08:59:34.172+0000] {task_command.py:467} INFO - Running <TaskInstance: ml_pipeline_demo.prepare_data manual__2025-03-05T08:59:26.992165+00:00 [running]> on host aacdd75e5d47
[2025-03-05T08:59:34.234+0000] {taskinstance.py:3134} INFO - Exporting env vars: AIRFLOW_CTX_DAG_OWNER='***' AIRFLOW_CTX_DAG_ID='ml_pipeline_demo' AIRFLOW_CTX_TASK_ID='prepare_data' AIRFLOW_CTX_EXECUTION_DATE='2025-03-05T08:59:26.992165+00:00' AIRFLOW_CTX_TRY_NUMBER='1' AIRFLOW_CTX_DAG_RUN_ID='manual__2025-03-05T08:59:26.992165+00:00'
[2025-03-05T08:59:34.236+0000] {logging_mixin.py:190} INFO - Task instance is in running state
[2025-03-05T08:59:34.237+0000] {logging_mixin.py:190} INFO -  Previous state of the Task instance: queued
[2025-03-05T08:59:34.237+0000] {logging_mixin.py:190} INFO - Current task name:prepare_data state:running start_date:2025-03-05 08:59:34.101013+00:00
[2025-03-05T08:59:34.237+0000] {logging_mixin.py:190} INFO - Dag name:ml_pipeline_demo and current dag run status:running
[2025-03-05T08:59:34.238+0000] {taskinstance.py:732} INFO - ::endgroup::
[2025-03-05T08:59:34.663+0000] {taskinstance.py:3313} ERROR - Task failed with exception
Traceback (most recent call last):
  File "/home/airflow/.local/lib/python3.12/site-packages/airflow/models/taskinstance.py", line 768, in _execute_task
    result = _execute_callable(context=context, **execute_callable_kwargs)
             ^^^^^^^^^^^^^^^^^^^^^^^^^^^^^^^^^^^^^^^^^^^^^^^^^^^^^^^^^^^^^
  File "/home/airflow/.local/lib/python3.12/site-packages/airflow/models/taskinstance.py", line 734, in _execute_callable
    return ExecutionCallableRunner(
           ^^^^^^^^^^^^^^^^^^^^^^^^
  File "/home/airflow/.local/lib/python3.12/site-packages/airflow/utils/operator_helpers.py", line 252, in run
    return self.func(*args, **kwargs)
           ^^^^^^^^^^^^^^^^^^^^^^^^^^
  File "/home/airflow/.local/lib/python3.12/site-packages/airflow/models/baseoperator.py", line 424, in wrapper
    return func(self, *args, **kwargs)
           ^^^^^^^^^^^^^^^^^^^^^^^^^^^
  File "/home/airflow/.local/lib/python3.12/site-packages/airflow/operators/python.py", line 238, in execute
    return_value = self.execute_callable()
                   ^^^^^^^^^^^^^^^^^^^^^^^
  File "/home/airflow/.local/lib/python3.12/site-packages/airflow/operators/python.py", line 256, in execute_callable
    return runner.run(*self.op_args, **self.op_kwargs)
           ^^^^^^^^^^^^^^^^^^^^^^^^^^^^^^^^^^^^^^^^^^^
  File "/home/airflow/.local/lib/python3.12/site-packages/airflow/utils/operator_helpers.py", line 252, in run
    return self.func(*args, **kwargs)
           ^^^^^^^^^^^^^^^^^^^^^^^^^^
  File "/opt/airflow/dags/ml_pipeline.py", line 16, in prepare_data
    df.drop(na)
            ^^
NameError: name 'na' is not defined
[2025-03-05T08:59:34.695+0000] {logging_mixin.py:190} INFO - Task instance in failure state
[2025-03-05T08:59:34.696+0000] {logging_mixin.py:190} INFO - Task start:2025-03-05 08:59:34.101013+00:00 end:2025-03-05 08:59:34.695022+00:00 duration:0.594009
[2025-03-05T08:59:34.697+0000] {logging_mixin.py:190} INFO - Task:<Task(PythonOperator): prepare_data> dag:<DAG: ml_pipeline_demo> dagrun:<DagRun ml_pipeline_demo @ 2025-03-05 08:59:26.992165+00:00: manual__2025-03-05T08:59:26.992165+00:00, state:running, queued_at: 2025-03-05 08:59:27.149698+00:00. externally triggered: True>
[2025-03-05T08:59:34.698+0000] {logging_mixin.py:190} INFO - Failure caused by name 'na' is not defined
[2025-03-05T08:59:34.699+0000] {taskinstance.py:1226} INFO - Marking task as FAILED. dag_id=ml_pipeline_demo, task_id=prepare_data, run_id=manual__2025-03-05T08:59:26.992165+00:00, execution_date=20250305T085926, start_date=20250305T085934, end_date=20250305T085934
[2025-03-05T08:59:34.735+0000] {taskinstance.py:341} INFO - ::group::Post task execution logs
[2025-03-05T08:59:34.736+0000] {standard_task_runner.py:124} ERROR - Failed to execute job 8 for task prepare_data (name 'na' is not defined; 207)
Traceback (most recent call last):
  File "/home/airflow/.local/lib/python3.12/site-packages/airflow/task/task_runner/standard_task_runner.py", line 117, in _start_by_fork
    ret = args.func(args, dag=self.dag)
          ^^^^^^^^^^^^^^^^^^^^^^^^^^^^^
  File "/home/airflow/.local/lib/python3.12/site-packages/airflow/cli/cli_config.py", line 49, in command
    return func(*args, **kwargs)
           ^^^^^^^^^^^^^^^^^^^^^
  File "/home/airflow/.local/lib/python3.12/site-packages/airflow/utils/cli.py", line 116, in wrapper
    return f(*args, **kwargs)
           ^^^^^^^^^^^^^^^^^^
  File "/home/airflow/.local/lib/python3.12/site-packages/airflow/cli/commands/task_command.py", line 483, in task_run
    task_return_code = _run_task_by_selected_method(args, _dag, ti)
                       ^^^^^^^^^^^^^^^^^^^^^^^^^^^^^^^^^^^^^^^^^^^^
  File "/home/airflow/.local/lib/python3.12/site-packages/airflow/cli/commands/task_command.py", line 256, in _run_task_by_selected_method
    return _run_raw_task(args, ti)
           ^^^^^^^^^^^^^^^^^^^^^^^
  File "/home/airflow/.local/lib/python3.12/site-packages/airflow/cli/commands/task_command.py", line 341, in _run_raw_task
    return ti._run_raw_task(
           ^^^^^^^^^^^^^^^^^
  File "/home/airflow/.local/lib/python3.12/site-packages/airflow/utils/session.py", line 97, in wrapper
    return func(*args, session=session, **kwargs)
           ^^^^^^^^^^^^^^^^^^^^^^^^^^^^^^^^^^^^^^
  File "/home/airflow/.local/lib/python3.12/site-packages/airflow/models/taskinstance.py", line 3006, in _run_raw_task
    return _run_raw_task(
           ^^^^^^^^^^^^^^
  File "/home/airflow/.local/lib/python3.12/site-packages/airflow/models/taskinstance.py", line 274, in _run_raw_task
    TaskInstance._execute_task_with_callbacks(
  File "/home/airflow/.local/lib/python3.12/site-packages/airflow/models/taskinstance.py", line 3161, in _execute_task_with_callbacks
    result = self._execute_task(context, task_orig)
             ^^^^^^^^^^^^^^^^^^^^^^^^^^^^^^^^^^^^^^
  File "/home/airflow/.local/lib/python3.12/site-packages/airflow/models/taskinstance.py", line 3185, in _execute_task
    return _execute_task(self, context, task_orig)
           ^^^^^^^^^^^^^^^^^^^^^^^^^^^^^^^^^^^^^^^
  File "/home/airflow/.local/lib/python3.12/site-packages/airflow/models/taskinstance.py", line 768, in _execute_task
    result = _execute_callable(context=context, **execute_callable_kwargs)
             ^^^^^^^^^^^^^^^^^^^^^^^^^^^^^^^^^^^^^^^^^^^^^^^^^^^^^^^^^^^^^
  File "/home/airflow/.local/lib/python3.12/site-packages/airflow/models/taskinstance.py", line 734, in _execute_callable
    return ExecutionCallableRunner(
           ^^^^^^^^^^^^^^^^^^^^^^^^
  File "/home/airflow/.local/lib/python3.12/site-packages/airflow/utils/operator_helpers.py", line 252, in run
    return self.func(*args, **kwargs)
           ^^^^^^^^^^^^^^^^^^^^^^^^^^
  File "/home/airflow/.local/lib/python3.12/site-packages/airflow/models/baseoperator.py", line 424, in wrapper
    return func(self, *args, **kwargs)
           ^^^^^^^^^^^^^^^^^^^^^^^^^^^
  File "/home/airflow/.local/lib/python3.12/site-packages/airflow/operators/python.py", line 238, in execute
    return_value = self.execute_callable()
                   ^^^^^^^^^^^^^^^^^^^^^^^
  File "/home/airflow/.local/lib/python3.12/site-packages/airflow/operators/python.py", line 256, in execute_callable
    return runner.run(*self.op_args, **self.op_kwargs)
           ^^^^^^^^^^^^^^^^^^^^^^^^^^^^^^^^^^^^^^^^^^^
  File "/home/airflow/.local/lib/python3.12/site-packages/airflow/utils/operator_helpers.py", line 252, in run
    return self.func(*args, **kwargs)
           ^^^^^^^^^^^^^^^^^^^^^^^^^^
  File "/opt/airflow/dags/ml_pipeline.py", line 16, in prepare_data
    df.drop(na)
            ^^
NameError: name 'na' is not defined
[2025-03-05T08:59:34.750+0000] {local_task_job_runner.py:266} INFO - Task exited with return code 1
[2025-03-05T08:59:34.781+0000] {taskinstance.py:3901} INFO - 0 downstream tasks scheduled from follow-on schedule check
[2025-03-05T08:59:34.787+0000] {local_task_job_runner.py:245} INFO - ::endgroup::
